<mujoco model="linearparticle">
  <compiler inertiafromgeom="true" angle="degree" coordinate="local" />
  <option timestep="0.01" eqsoft="true" remotecontact="true" gravity="0 0 0" iterations="20" />

  <default>
    <joint islimited="false" damping="1" makeactuator="true" />
    <geom contype="2" conaffinity="1" condim="1" friction=".5 .1 .1"
          density="1000" mindist="0.002" compliance="0.001"
          timeconst="0.01" />
  </default>

  <body>
    <body name="particle" pos="0 0 0">
      <geom name="particle_geom" type="capsule" fromto="-0.01 0 0 0.01 0 0" size="0.05" />
      <site name="particle_site" pos="0 0 0" />
      <joint name="ball_x" type="slide" pos="0 0 0" axis="1 0 0" />
      <joint name="ball_y" type="slide" pos="0 0 0" axis="0 1 0" />
    </body>
  </body>

  <features>
    <feature name='control'>
      <data field='ctrl' item='all'/>
    </feature>
  </features>

  <costs>
    <physics_options  timestep='0.01'/>
    <optimization_options logeps='-30' horizon='400' logmurange='-5 3' />
    <cost name='dummy'>
      <term feature='control' norm='quadratic' coef_running='.1' />
    </cost>
  </costs>
</mujoco>